<robot xmlns:xacro="http://www.ros.org/wiki/xacro" name="rover_mini_2wd">

    <!-- Robot Parameters -->
    <xacro:property name="wheel_z_offset" value="0.023" />
    <xacro:property name="wheel_x_offset" value="0.107" />
    <xacro:property name="wheel_y_offset" value="0.162" />
    <xacro:property name="wheel_mass" value="3.62874" />
    <xacro:property name="chassis_mass" value="1.36078" />
    <xacro:property name="castor_mass" value="0.2" /> 
    <xacro:property name="castor_housing_mass" value="0.35" />
    <xacro:property name="castor_x_offset" value="0.0" />
    <xacro:property name="castor_y_offset" value="0.09" />
    <xacro:property name="castor_z_offset" value="0.018" />

    <!-- Part Includes - Payload, Sensors, Etc.. -->
    <!-- Comment or Uncomment any of these to add them to the dev payload -->
    <!-- You can always link them elsewhere if you wish by editing accessories/<sensor>.urdf -->
    <!-- <xacro:property name="payload_z_offset" value="0.1198" />
    <xacro:include filename="$(find roverrobotics_description)/urdf/accessories/rover_dev_payload.urdf" />
    <xacro:include filename="$(find roverrobotics_description)/urdf/accessories/rplidar_s2.urdf" />
    <xacro:include filename="$(find roverrobotics_description)/urdf/accessories/imu.urdf" /> -->

    <!-- Robot Description -->
    <link name="base_link" />
    <link name="chassis_link">
        <visual>
            <origin xyz="0 0 0" rpy="0 -0 1.5708" />
            <geometry>
                <mesh filename="file://$(find roverrobotics_description)/meshes/mini_2wd_chassis.dae"/>
            </geometry>
        </visual>

        <collision>
            <origin xyz="0 0 0" rpy="0 -0 1.5708" />
            <geometry>
                <mesh filename="file://$(find roverrobotics_description)/meshes/mini_2wd_chassis.dae"/>
            </geometry>
        </collision>

        <inertial>
            <origin xyz="0 0 0.02" rpy="0 0 0"/>
            <mass value="${chassis_mass}" />
            <inertia ixx="0.006453" ixy="0"  ixz="0" iyy="0.0117" iyz="0" izz="0.015812" />
        </inertial>
    </link>

    <joint name="base_to_chassis" type="fixed">
        <parent link="base_link"/>
        <child link="chassis_link"/>
        <origin xyz="0 0 0.058"/>
    </joint>

    <link name="fr_wheel_link">
        <visual>
            <origin xyz="0 0.08 0" rpy="1.57 3.1415 3.1415" />
            <geometry>
                <mesh filename="file://$(find roverrobotics_description)/meshes/65wheels.dae"/>
            </geometry>
        </visual>

        <collision>
            <origin xyz="0 0.08 0" rpy="1.57 3.1415 3.1415" />
            <geometry>
                <mesh filename="file://$(find roverrobotics_description)/meshes/65wheels.dae"/>
            </geometry>
        </collision>

        <inertial>
            <origin xyz="0 0 0" rpy="0 0 0" />
            <mass value="${wheel_mass}" />
            <inertia ixx="0.008093" ixy="0"  ixz="0" iyy="0.014226" iyz="0" izz="0.008093" />
        </inertial>
        <mu>5.0</mu>
    </link>
    <joint name="fr_wheel_to_chassis" type="continuous">
        <parent link="chassis_link"/>
        <child link="fr_wheel_link"/>
        <axis xyz="0 1 0"/>
        <origin xyz="${wheel_x_offset} ${-wheel_y_offset} ${wheel_z_offset}"/>
    </joint>

    <link name="fl_wheel_link">
        <visual>
            <origin xyz="0 -0.08 0" rpy="1.57 3.1415 0" />
            <geometry>
                <mesh filename="file://$(find roverrobotics_description)/meshes/65wheels.dae"/>
            </geometry>
        </visual>

        <collision>
            <origin xyz="0 -0.08 0" rpy="1.57 3.1415 0" />
            <geometry>
                <mesh filename="file://$(find roverrobotics_description)/meshes/65wheels.dae"/>
            </geometry>
        </collision>

        <inertial>
            <origin xyz="0 0 0" rpy="0 0 0" />
            <mass value="${wheel_mass}" />
            <inertia ixx="0.008093" ixy="0"  ixz="0" iyy="0.014226" iyz="0" izz="0.008093" />
        </inertial>
        <mu>5.0</mu>
    </link>
    <joint name="fl_wheel_to_chassis" type="continuous">
        <parent link="chassis_link"/>
        <child link="fl_wheel_link"/>
        <axis xyz="0 1 0"/>
        <origin xyz="${wheel_x_offset} ${wheel_y_offset} ${wheel_z_offset}"/>
    </joint>

    <link name="rl_castor_housing_link">
        <visual>
            <origin xyz="0 0 0" rpy="1.57 0 1.57" />
            <geometry>
                <mesh filename="file://$(find roverrobotics_description)/meshes/castor_housing.dae"/>
            </geometry>
        </visual>

        <collision>
            <origin xyz="0 0 0" rpy="1.57 0 1.57" />
            <geometry>
                <mesh filename="file://$(find roverrobotics_description)/meshes/castor_housing.dae"/>
            </geometry>
        </collision>

        <inertial>
            <origin xyz="0 0 0" rpy="0 0 0" />
            <mass value="${castor_housing_mass}" />
            <inertia ixx="0.0003187" ixy="0.0"  ixz="0.0" iyy="0.0003187" iyz="0.0" izz="0.0001764" />
        </inertial>
        <mu>5.0</mu>
    </link>
    <joint name="rl_ch_to_chassis" type="continuous">
        <parent link="chassis_link"/>
        <child link="rl_castor_housing_link"/>
        <axis xyz="0 0 1"/>
        <origin xyz="${-wheel_x_offset - castor_x_offset} ${castor_y_offset + 0.0025} ${castor_z_offset}" rpy="0 0 0"/>
    </joint>
    <link name="rl_castor_link">
        <visual>
            <origin xyz="0 0 0" rpy="1.57 0 1.57" />
            <geometry>
                <mesh filename="file://$(find roverrobotics_description)/meshes/castor.dae"/>
            </geometry>
        </visual>

        <collision>
            <origin xyz="0 0 0" rpy="1.57 0 1.57" />
            <geometry>
                <mesh filename="file://$(find roverrobotics_description)/meshes/castor.dae"/>
            </geometry>
        </collision>

        <inertial>
            <origin xyz="0 0 0" rpy="0 0 0" />
            <mass value="${castor_mass}" />
            <inertia ixx="0.00013978" ixy="0.0"  ixz="0.0" iyy="0.00025806" iyz="0.0" izz="0.00013978" />
        </inertial>
        <mu>5.0</mu>
    </link>
    <joint name="rl_castor_to_chassis" type="continuous">
        <parent link="rl_castor_housing_link"/>
        <child link="rl_castor_link"/>
        <axis xyz="0 1 0"/>
        <origin xyz="-0.031 0 -0.027" rpy="0 0 0"/>
    </joint>


    <link name="rr_castor_housing_link">
        <visual>
            <origin xyz="0 0 0" rpy="1.57 0 1.57" />
            <geometry>
                <mesh filename="file://$(find roverrobotics_description)/meshes/castor_housing.dae"/>
            </geometry>
        </visual>

        <collision>
            <origin xyz="0 0 0" rpy="1.57 0 1.57" />
            <geometry>
                <mesh filename="file://$(find roverrobotics_description)/meshes/castor_housing.dae"/>
            </geometry>
        </collision>

        <inertial>
            <origin xyz="0 0 0" rpy="0 0 0" />
            <mass value="${castor_housing_mass}" />
            <inertia ixx="0.0003187" ixy="0.0"  ixz="0.0" iyy="0.0003187" iyz="0.0" izz="0.0001764" />
        </inertial>
        <mu>5.0</mu>
    </link>
    <joint name="rr_ch_to_chassis" type="continuous">
        <parent link="chassis_link"/>
        <child link="rr_castor_housing_link"/>
        <axis xyz="0 0 1"/>
        <origin xyz="${-wheel_x_offset - castor_x_offset} ${-castor_y_offset} ${castor_z_offset}" rpy="0 0 0"/>
    </joint>
    <link name="rr_castor_link">
        <visual>
            <origin xyz="0 0 0" rpy="1.57 0 1.57" />
            <geometry>
                <mesh filename="file://$(find roverrobotics_description)/meshes/castor.dae"/>
            </geometry>
        </visual>

        <collision>
            <origin xyz="0 0 0" rpy="1.57 0 1.57" />
            <geometry>
                <mesh filename="file://$(find roverrobotics_description)/meshes/castor.dae"/>
            </geometry>
        </collision>

        <inertial>
            <origin xyz="0 0 0" rpy="0 0 0" />
            <mass value="${castor_mass}" />
            <inertia ixx="0.00013978" ixy="0.0"  ixz="0.0" iyy="0.00025806" iyz="0.0" izz="0.00013978" />
        </inertial>
        <mu>5.0</mu>
    </link>
    <joint name="rr_castor_to_chassis" type="continuous">
        <parent link="rr_castor_housing_link"/>
        <child link="rr_castor_link"/>
        <axis xyz="0 1 0"/>
        <origin xyz="-0.031 0 -0.027" rpy="0 0 0"/>
    </joint>

    <gazebo>
        <plugin name="ignition::gazebo::systems::DiffDrive" filename="ignition-gazebo-diff-drive-system"> 
            <num_wheel_pairs>2</num_wheel_pairs>
            <!-- Wheel Information -->
            <left_joint>fl_wheel_to_chassis</left_joint>
            <right_joint>fr_wheel_to_chassis</right_joint>
            <wheel_separation>0.26</wheel_separation>
            <wheel_radius>0.08</wheel_radius>

            <!-- Limits -->
            <max_linear_acceleration>5</max_linear_acceleration>
            <min_linear_acceleration>-5</min_linear_acceleration>
            <max_angular_acceleration>4</max_angular_acceleration>
            <min_angular_acceleration>-4</min_angular_acceleration>

            
            <!-- Output -->
            <frame_id>odom</frame_id>
            <child_frame_id>base_link</child_frame_id>

            <!-- Topics -->
            <topic>/cmd_vel</topic>
            <odom_topic>/odometry/wheels</odom_topic>
            <tf_topic>/tf_gazebo</tf_topic>

        </plugin>

        <plugin filename="ignition-gazebo-joint-state-publisher-system" name="ignition::gazebo::systems::JointStatePublisher">
            <topic>/joint_states</topic>
        </plugin>
    </gazebo>

    <gazebo reference="fl_wheel_link">
        <mu1 value="200.0" />
        <mu2 value="200.0" />
        <kp  value="1000000.0" />
        <kd  value="1.0" />
        <minDepth>0.005</minDepth>
    </gazebo>
    <gazebo reference="fr_wheel_link">
        <mu1 value="200.0" />
        <mu2 value="200.0" />
        <kp  value="1000000.0" />
        <kd  value="1.0" />
        <minDepth>0.005</minDepth>
    </gazebo>
    <gazebo reference="rl_wheel_link">
        <mu1 value="200.0" />
        <mu2 value="200.0" />
        <kp  value="1000000.0" />
        <kd  value="1.0" />
        <minDepth>0.005</minDepth>
    </gazebo>
    <gazebo reference="rr_wheel_link">
        <mu1 value="200.0" />
        <mu2 value="200.0" />
        <kp  value="1000000.0" />
        <kd  value="1.0" />
        <minDepth>0.005</minDepth>
    </gazebo>

</robot>
